Workbook

Sheet قابلیت‌ها
A1: ردیف | B1: قابلیت (نام در پریمیر) | C1: نام فارسی | D1: چه کار می‌کند و هدفش چیست | E1: پشت صحنه: پریمیر چطور این کار را انجام می‌دهد | F1: دسته | G1: کجا / میان‌بر (ویندوز) | H1: نوع پردازش | I1: ارتقای کیفیت تصویر/صدا
A2: 1 | B2: Project (.prproj) | C2: پروژه | D2: فایلی که همه‌ی کلیپ‌ها، سکانس‌ها، جلوه‌ها و تنظیمات کار را سازمان می‌دهد؛ خود ویدیوها داخلش نیستند. | E2: فایل پروژه یک XML فشرده ‪(gzip)‬ است که فقط مسیر فایل‌های رسانه، نقاط ورود و خروج، ترتیب کلیپ‌ها و پارامتر جلوه‌ها را نگه می‌دارد؛ برای همین کوچک است و جابه‌جا کردن فایل‌های رسانه باعث «آفلاین» شدن کلیپ‌ها می‌شود. | F2: پروژه و مدیریت رسانه | G2: File > New > Project · Ctrl+Alt+N | H2: مدیریتی، رابط و جریان کار
A3: 2 | B3: Multiple Open Projects & Project Locking | C3: چند پروژه‌ی باز و قفل پروژه | D3: باز کردن هم‌زمان چند پروژه و جلوگیری از ویرایش هم‌زمان یک پروژه توسط دو نفر. | E3: هر پروژه‌ی باز یک مدل داده‌ی جدا در حافظه است؛ قفل با یک فایل نشانگر (‎.prlock‎) کنار پروژه اعلام می‌کند چه کسی در حال ویرایش است. | F3: پروژه و مدیریت رسانه | G3: File > Open Project · Preferences > Collaboration | H3: مدیریتی، رابط و جریان کار
A4: 3 | B4: Project Panel Views | C4: نماهای پنل پروژه (لیست، آیکن، آزاد) | D4: نمایش کلیپ‌ها به‌صورت فهرست با ستون‌های متادیتا، شبکه‌ی آیکن یا چیدمان آزاد ‪(Freeform)‬ مثل استوری‌بورد. | E4: نمای لیست روی متادیتای کلیپ‌ها مرتب‌سازی و فیلتر می‌کند؛ Freeform مختصات هر آیتم را ذخیره می‌کند تا چیدمان دلخواه بماند؛ Hover Scrub فریم متناظر با موقعیت ماوس را نشان می‌دهد. | F4: پروژه و مدیریت رسانه | G4: Window > Project | H4: مدیریتی، رابط و جریان کار
A5: 4 | B5: Bins & Search Bins | C5: بین‌ها و بین‌های جست‌وجو | D5: پوشه‌های داخل پروژه برای مرتب کردن رسانه؛ Search Bin بر اساس یک جست‌وجو خودکار پر می‌شود. | E5: بین فقط یک گره در درخت پروژه است و فایل‌ها روی دیسک جابه‌جا نمی‌شوند؛ Search Bin یک پرس‌وجوی ذخیره‌شده روی متادیتاست که با هر تغییر دوباره اجرا می‌شود. | F5: پروژه و مدیریت رسانه | G5: Ctrl+/ · File > New > Search Bin | H5: مدیریتی، رابط و جریان کار
A6: 5 | B6: Media Browser & Import | C6: مرورگر رسانه و وارد کردن | D6: مرور کارت‌ها و پوشه‌ها و وارد کردن فایل‌ها با پیش‌نمایش؛ ساختار پوشه‌ی دوربین‌ها (مثل XDCAM، P2 و AVCHD) را می‌شناسد. | E6: ساختار استاندارد پوشه‌ی کارت دوربین تحلیل می‌شود تا فایل‌های تکه‌تکه‌ی یک ضبط طولانی ‪(Spanned Clips)‬ به‌صورت یک کلیپ پیوسته و با متادیتای درست وارد شوند. | F6: پروژه و مدیریت رسانه | G6: Shift+8 · Ctrl+I | H6: مدیریتی، رابط و جریان کار
A7: 6 | B7: Supported Formats & Camera RAW | C7: فرمت‌ها و RAW دوربین | D7: پشتیبانی از فرمت‌های رایج و حرفه‌ای (H.264، HEVC، ProRes، DNx، XAVC، RED، ARRIRAW، Blackmagic RAW، ProRes RAW و ...)؛ در ۲۶.۵ پشتیبانی Sony FX5، ARRICORE و ProRes RAW بهتر شده است. | E7: هر فرمت با یک رمزگشا ‪(Decoder)‬ خوانده می‌شود؛ در فرمت‌های RAW، دموزاییک و تبدیل رنگ در خود برنامه انجام می‌شود و تنظیمات منبع ‪(Source Settings)‬ قابل تغییر است. | F7: پروژه و مدیریت رسانه | G7: File > Import | H7: کدک، رمزگشایی و رندر
A8: 7 | B8: Image Sequences | C8: دنباله‌ی تصاویر | D8: وارد کردن مجموعه‌ای از عکس‌های شماره‌دار (تایم‌لپس یا رندر سه‌بعدی) به‌صورت یک کلیپ ویدیویی. | E8: فایل‌ها بر اساس الگوی شماره مرتب و هر تصویر به یک فریم با نرخ فریم پیش‌فرض (قابل تغییر در Interpret Footage) نگاشت می‌شود. | F8: پروژه و مدیریت رسانه | G8: Import > تیک Image Sequence | H8: مدیریتی، رابط و جریان کار
A9: 8 | B9: Photoshop & Illustrator Files | C9: فایل‌های فتوشاپ و ایلاستریتور | D9: وارد کردن PSD به‌صورت لایه‌های جدا (به شکل سکانس) یا ادغام‌شده، و فایل‌های برداری ایلاستریتور. | E9: هر لایه‌ی PSD با حالت ترکیب و شفافیتش به یک کلیپ جدا تبدیل و در یک سکانس روی هم چیده می‌شود؛ فایل‌های برداری با Vector Motion در هر مقیاس دوباره پیکسلی می‌شوند. | F9: پروژه و مدیریت رسانه | G9: File > Import | H9: ترکیب لایه و شفافیت
A10: 9 | B10: Interpret Footage | C10: تفسیر فوتیج | D10: تغییر نحوه‌ی تفسیر فایل: نرخ فریم (برای آهسته کردن)، نسبت پیکسل، ترتیب فیلدها، آلفا و فضای رنگی. | E10: فقط متادیتای تفسیر در پروژه عوض می‌شود؛ مثلاً اگر فوتیج ۱۲۰ فریمی به‌صورت ۲۴ فریم تفسیر شود، هر فریم یک‌به‌یک پخش و ویدیو ۵ برابر کندتر بدون درون‌یابی می‌شود. | F10: پروژه و مدیریت رسانه | G10: Clip > Modify > Interpret Footage | H10: زمانی (بین فریم‌ها)
A11: 10 | B11: Media Intelligence Search | C11: جست‌وجوی هوشمند رسانه | D11: جست‌وجوی کلیپ‌ها با توصیف محتوا (مثلاً «ماشین قرمز در غروب»)، گفتار، صدا و تصاویر مشابه در پنل Search. | E11: کلیپ‌ها تحلیل و برای فریم‌ها و صدا بردارهای ویژگی ‪(Embedding)‬ ساخته می‌شود؛ متن جست‌وجو هم به همان فضای برداری برده و نزدیک‌ترین بردارها به‌عنوان نتیجه برگردانده می‌شوند. | F11: پروژه و مدیریت رسانه | G11: Window > Search | H11: هوش مصنوعی (دستگاه یا ابر)
A12: 11 | B12: Markers | C12: مارکرها | D12: علامت‌گذاری لحظه‌ها روی کلیپ یا سکانس با نام، رنگ، توضیح و مدت؛ از ۲۶.۲ جست‌وجو بر اساس نام، توضیح و رنگ. | E12: هر مارکر یک رکورد زمانی (تایم‌کد، مدت، رنگ، متن) در متادیتای کلیپ یا سکانس است و می‌تواند به After Effects یا Frame.io منتقل شود. | F12: پروژه و مدیریت رسانه | G12: کلید M · Window > Markers | H12: مدیریتی، رابط و جریان کار
A13: 12 | B13: Metadata & Labels | C13: متادیتا و برچسب‌ها | D13: مشاهده و ویرایش اطلاعات کلیپ (دوربین، تاریخ، صحنه، نما) و رنگ برچسب برای سازمان‌دهی. | E13: متادیتا به‌صورت XMP داخل فایل یا در پروژه ذخیره می‌شود و در ستون‌های پنل پروژه قابل مرتب‌سازی و جست‌وجوست. | F13: پروژه و مدیریت رسانه | G13: Window > Metadata | H13: مدیریتی، رابط و جریان کار
... A77: 76 | B77: Frame Blending | C77: ترکیب فریم | D77: نرم‌تر کردن حرکت آهسته با مخلوط کردن فریم‌های مجاور. | E77: فریم میانی ترکیب وزن‌دار دو فریم منبع مجاور است، که ظاهری شبح‌دار ‪(Ghosting)‬ ایجاد می‌کند. | F77: سرعت و زمان | G77: Time Interpolation > Frame Blending | H77: زمانی (بین فریم‌ها)
A78: 77 | B78: Optical Flow | C78: جریان نوری | D78: ساختن فریم‌های میانی واقعی برای حرکت آهسته‌ی نرم. | E78: برای هر پیکسل بردار حرکت بین دو فریم تخمین زده (جریان نوری) و فریم جدید با جابه‌جا کردن پیکسل‌ها در میانه‌ی مسیر ساخته می‌شود؛ در حرکت‌های پیچیده یا هم‌پوشان ممکن است اعوجاج ایجاد کند. | F78: سرعت و زمان | G78: Time Interpolation > Optical Flow | H78: تخمین و ردیابی حرکت | I78: ✓
A79: 78 | B79: Echo | C79: پژواک ‪(Echo)‬ | D79: تکرار فریم‌های قبلی با کم‌رنگی برای جلوه‌ی ردپای حرکت. | E79: چند فریم با فاصله‌ی زمانی Echo Time خوانده و با ضریب کاهشی و عملگر ترکیب (مثل Add یا Maximum) روی هم ترکیب می‌شوند. | F79: سرعت و زمان | G79: Effects > Time > Echo | H79: زمانی (بین فریم‌ها)
A80: 79 | B80: Posterize Time | C80: پوستری کردن زمان | D80: کاهش نرخ فریم ظاهری برای حس استاپ‌موشن یا کارتونی. | E80: هر فریم منبع برای چند فریم خروجی تکرار می‌شود تا نرخ فریم مؤثر به مقدار داده‌شده برسد. | F80: سرعت و زمان | G80: Effects > Time > Posterize Time | H80: زمانی (بین فریم‌ها)
A81: 80 | B81: Time Tuner | C81: تنظیم‌گر زمان | D81: کوتاه یا بلند کردن نامحسوس طول ویدیو هنگام خروجی برای رسیدن به مدت دقیق پخش. | E81: فریم‌هایی در نقاط کم‌تحرک یا نزدیک برش‌ها به‌طور نامحسوس حذف یا تکرار می‌شوند. | F81: سرعت و زمان | G81: Export > Effects > Time Tuner | H81: زمانی (بین فریم‌ها)
A82: 81 | B82: Motion | C82: حرکت ‪(Motion)‬ | D82: تغییر موقعیت، اندازه، چرخش و نقطه‌ی لنگر کلیپ؛ پایه‌ی تصویر در تصویر و انیمیشن. | E82: ماتریس تبدیل آفین روی هر فریم اعمال و پیکسل‌ها با درون‌یابی نمونه‌برداری می‌شوند (با Maximum Render Quality درون‌یابی دقیق‌تر). | F82: حرکت، کی‌فریم و ماسک | G82: Effect Controls > Motion | H82: هندسی (نگاشت مختصات و درون‌یابی)
A83: 82 | B83: Anti-flicker Filter | C83: فیلتر ضد لرزش | D83: کاهش لرزش خطوط افقی ریز (مثل متن نازک) در نمایش درهم‌رفته یا کوچک‌نمایی. | E83: یک محو عمودی ملایم که اختلاف روشنایی بین ردیف‌های مجاور را کم می‌کند. | F83: حرکت، کی‌فریم و ماسک | G83: Effect Controls > Motion > Anti-flicker Filter | H83: همسایگی مکانی (کانولوشن و فیلتر محلی)
A84: 83 | B84: Opacity & Blend Modes | C84: شفافیت و حالت‌های ترکیب | D84: کم‌رنگ کردن کلیپ و ترکیب آن با کلیپ‌های زیر با حالت‌هایی مثل Multiply، Screen و Overlay. | E84: شفافیت ضریب آلفاست؛ حالت‌های ترکیب همان فرمول‌های فتوشاپ‌اند (مثلاً Multiply = a×b و ‪Screen = 1−(1−a)(1−b)‬) که برای هر پیکسل هر فریم اجرا می‌شوند. | F84: حرکت، کی‌فریم و ماسک | G84: Effect Controls > Opacity | H84: ترکیب لایه و شفافیت
A85: 84 | B85: Keyframes | C85: کی‌فریم‌ها | D85: متحرک کردن هر پارامتر با تعیین مقدار آن در زمان‌های مختلف. | E85: بین کی‌فریم‌ها مقدار پارامتر برای هر فریم با تابع درون‌یابی محاسبه می‌شود؛ پس فقط چند نقطه ذخیره می‌شود نه مقدار همه‌ی فریم‌ها. | F85: حرکت، کی‌فریم و ماسک | G85: آیکن ساعت در Effect Controls | H85: مدیریتی، رابط و جریان کار
A86: 85 | B86: Keyframe Interpolation | C86: درون‌یابی کی‌فریم | D86: نوع حرکت بین کی‌فریم‌ها: خطی، بزیه، بزیه‌ی خودکار، بزیه‌ی پیوسته، ثابت ‪(Hold)‬ و Ease In/Out. | E86: خطی مقدار را با شیب ثابت عوض می‌کند؛ بزیه از منحنی مکعبی با دستگیره استفاده می‌کند؛ Hold مقدار را تا کی‌فریم بعدی ثابت نگه می‌دارد؛ Ease شیب را نزدیک کی‌فریم به صفر می‌رساند تا حرکت نرم شروع و تمام شود. | F86: حرکت، کی‌فریم و ماسک | G86: راست‌کلیک روی کی‌فریم | H86: هندسی (نگاشت مختصات و درون‌یابی)
A87: 86 | B87: Value & Velocity Graphs | C87: نمودار مقدار و سرعت | D87: تنظیم دقیق شتاب حرکت با منحنی‌ها. | E87: نمودار سرعت مشتق منحنی مقدار است؛ تغییر دستگیره‌ها شکل منحنی بزیه و در نتیجه شتاب را عوض می‌کند. | F87: حرکت، کی‌فریم و ماسک | G87: Effect Controls > باز کردن پارامتر | H87: مدیریتی، رابط و جریان کار
A88: 87 | B88: Transform Effect | C88: جلوه‌ی تبدیل ‪(Transform)‬ | D88: مثل Motion ولی با جایگاه قابل‌کنترل بین جلوه‌ها و محو حرکتی ‪(Shutter Angle)‬. | E88: تبدیل هندسی در همان جایگاه پشته‌ی جلوه‌ها اعمال می‌شود؛ محو حرکتی با نمونه‌برداری چند موقعیت میانی در بازه‌ی باز بودن شاتر و میانگین آن‌ها ساخته می‌شود. | F88: حرکت، کی‌فریم و ماسک | G88: Effects > Distort > Transform | H88: هندسی (نگاشت مختصات و درون‌یابی)
A89: 88 | B89: Crop | C89: برش کادر | D89: بریدن لبه‌های تصویر؛ برای تصویر در تصویر، نوار سینمایی و حذف حاشیه. | E89: پیکسل‌های بیرون ناحیه شفاف (آلفا صفر) می‌شوند و Edge Feather لبه را نرم می‌کند. | F89: حرکت، کی‌فریم و ماسک | G89: Effects > Transform > Crop | H89: هندسی (نگاشت مختصات و درون‌یابی)
A90: 89 | B90: Shape Masks | C90: ماسک‌های شکلی | D90: محدود کردن جلوه یا شفافیت به بیضی، مستطیل یا شکل دلخواه با قلم، با Feather، Opacity، Expansion و Invert. | E90: ماسک یک مسیر برداری است که در هر فریم به آلفای جلوه تبدیل می‌شود؛ Feather محو لبه و Expansion اتساع یا سایش مسیر است. | F90: حرکت، کی‌فریم و ماسک | G90: Effect Controls > آیکن‌های ماسک | H90: برداری و گرافیک
... A102: 101 | B102: Alpha Adjust | C102: تنظیم آلفا | D102: معکوس کردن، نادیده گرفتن یا نمایش کانال آلفا به‌صورت ماسک. | E102: کانال آلفا در ضریب ضرب، معکوس یا به‌صورت تصویر خاکستری نمایش داده می‌شود. | F102: کلید و ترکیب | G102: Effects > Keying > Alpha Adjust | H102: کلید و آلفا (ماتینگ)
A103: 102 | B103: Warp Stabilizer (Analysis) | C103: تثبیت‌کننده‌ی Warp (تحلیل) | D103: حذف لرزش دوربین روی دست با تحلیل خودکار حرکت. | E103: نقاط ویژگی در فریم‌ها ردیابی و مسیر حرکت دوربین تخمین زده می‌شود؛ مسیر صاف‌شده محاسبه و هر فریم با تبدیل هندسی به مسیر جدید برده می‌شود؛ پایه‌ی آن پژوهش ادوبی در تثبیت ویدیو ‪(Subspace Video Stabilization)‬ است. | F103: تثبیت و ترمیم تصویر | G103: Effects > Distort > Warp Stabilizer | H103: تخمین و ردیابی حرکت | I103: ✓
A104: 103 | B104: Warp Stabilizer (Method & Framing) | C104: روش و کادربندی تثبیت | D104: انتخاب نوع اصلاح (Position، Position/Scale/Rotation، Perspective، Subspace Warp) و نحوه‌ی پر کردن لبه‌ها (Crop، Auto-scale، Synthesize Edges). | E104: Subspace Warp به‌جای یک تبدیل کلی، تصویر را با یک مش تاب می‌دهد تا اعوجاج پارالاکس اصلاح شود؛ Synthesize Edges لبه‌های خالی را از فریم‌های قبل و بعد پر می‌کند؛ Rolling Shutter Ripple لرزش ژله‌ای سنسور را جبران می‌کند. | F104: تثبیت و ترمیم تصویر | G104: Warp Stabilizer > Advanced | H104: تخمین و ردیابی حرکت | I104: ✓
A105: 104 | B105: Rolling Shutter Repair | C105: ترمیم رولینگ شاتر | D105: اصلاح کج و ژله‌ای شدن تصویر در حرکت سریع دوربین‌های CMOS. | E105: سنسور ردیف‌ها را پشت‌سرهم می‌خواند؛ حرکت تخمین و با تاخیر زمانی هر ردیف جبران می‌شود تا تصویر صاف شود. | F105: تثبیت و ترمیم تصویر | G105: Effects > Distort > Rolling Shutter Repair | H105: تخمین و ردیابی حرکت | I105: ✓
A106: 105 | B106: Lens Distortion | C106: اعوجاج لنز | D106: حذف یا افزودن اعوجاج بشکه‌ای (مثلاً فیش‌آی دوربین‌های ورزشی). | E106: نگاشت شعاعی مختصات با ضریب Curvature و مرکز قابل‌جابه‌جایی؛ برای حذف اعوجاج، معکوس مدل لنز اعمال می‌شود. | F106: تثبیت و ترمیم تصویر | G106: Effects > Distort > Lens Distortion | H106: هندسی (نگاشت مختصات و درون‌یابی) | I106: ✓
A107: 106 | B107: Reduce Interlace Flicker | C107: کاهش لرزش درهم‌رفتگی | D107: کاهش لرزش خطوط افقی نازک در نمایش درهم‌رفته. | E107: محو عمودی خفیف بین ردیف‌های مجاور. | F107: تثبیت و ترمیم تصویر | G107: Effects > Blur & Sharpen > Reduce Interlace Flicker | H107: همسایگی مکانی (کانولوشن و فیلتر محلی) | I107: ✓
A108: 107 | B108: Lumetri Color | C108: لومتری کالر | D108: مجموعه‌ی کامل تصحیح و درجه‌بندی رنگ در یک جلوه با بخش‌های Basic، Creative، Curves، Color Wheels، HSL Secondary و Vignette. | E108: پردازش روی GPU با دقت ۳۲ بیت اعشاری و به ترتیب ثابت بخش‌ها انجام می‌شود؛ هر بخش در اصل یک تابع نقطه‌ای رنگ است که کل زنجیره را می‌توان در یک LUT سه‌بعدی خلاصه کرد. | F108: رنگ: لومتری (Lumetri) | G108: Window > Lumetri Color | H108: نقطه‌ای رنگ (هر پیکسل مستقل، LUT)
A109: 108 | B109: Input LUT | C109: LUT ورودی | D109: تبدیل فوتیج لاگ (مثل S-Log یا V-Log) به رنگ عادی قبل از بقیه‌ی تنظیمات. | E109: جدول جست‌وجوی سه‌بعدی هر رنگ ورودی را به رنگ خروجی نگاشت و رنگ‌های بین نقاط جدول را با درون‌یابی حساب می‌کند. | F109: رنگ: لومتری (Lumetri) | G109: Lumetri > Basic Correction > Input LUT | H109: نقطه‌ای رنگ (هر پیکسل مستقل، LUT) | I109: ✓
A110: 109 | B110: White Balance (Lumetri) | C110: تعادل سفیدی (لومتری) | D110: رفع ته‌رنگ با قطره‌چکان یا لغزنده‌های Temperature و Tint. | E110: ضرایب کانال‌ها طوری تنظیم می‌شوند که پیکسل نمونه خاکستری خنثی شود. | F110: رنگ: لومتری (Lumetri) | G110: Lumetri > Basic Correction | H110: نقطه‌ای رنگ (هر پیکسل مستقل، LUT) | I110: ✓
A111: 110 | B111: Tone (Lumetri) | C111: تُن: نوردهی، کنتراست، روشنی‌ها و سایه‌ها | D111: تنظیم Exposure، Contrast، Highlights، Shadows، Whites و Blacks. | E111: هر لغزنده بخشی از منحنی تُن را تغییر می‌دهد: Exposure ضرب مقادیر، Contrast منحنی S حول میانه، و Whites و Blacks دو سر منحنی. | F111: رنگ: لومتری (Lumetri) | G111: Lumetri > Basic Correction | H111: نقطه‌ای رنگ (هر پیکسل مستقل، LUT) | I111: ✓
A112: 111 | B112: Auto (Lumetri) | C112: تنظیم خودکار لومتری | D112: اصلاح خودکار نور و رنگ پایه با یک کلیک. | E112: مدل یادگیری ماشین ‪(Adobe Sensei)‬ فریم را تحلیل و مقادیر لغزنده‌های Basic را پیشنهاد می‌کند. | F112: رنگ: لومتری (Lumetri) | G112: Lumetri > Basic Correction > Auto | H112: هوش مصنوعی روی دستگاه | I112: ✓
A113: 112 | B113: Saturation (Lumetri) | C113: اشباع | D113: کم یا زیاد کردن شدت همه‌ی رنگ‌ها. | E113: فاصله‌ی رنگ هر پیکسل از محور خاکستری در یک ضریب ضرب می‌شود. | F113: رنگ: لومتری (Lumetri) | G113: Lumetri > Basic Correction | H113: نقطه‌ای رنگ (هر پیکسل مستقل، LUT)
A114: 113 | B114: Creative Look | C114: لوک خلاقانه | D114: اعمال لوک آماده‌ی سینمایی با قابلیت تنظیم شدت. | E114: یک LUT سه‌بعدی اعمال و با لغزنده‌ی Intensity با تصویر اصلی مخلوط می‌شود. | F114: رنگ: لومتری (Lumetri) | G114: Lumetri > Creative | H114: نقطه‌ای رنگ (هر پیکسل مستقل، LUT)
...

Sheet خلاصه
A1: خلاصه‌ی پایگاه داده‌ی قابلیت‌های پریمیر
A2: همه‌ی اعداد این برگه با فرمول از برگه‌ی «قابلیت‌ها» شمرده می‌شوند و با تغییر داده‌ها خودکار به‌روز می‌شوند.
A4: دسته | B4: تعداد قابلیت‌ها | C4: قابلیت‌های ارتقای کیفیت (✓)
A5: پروژه و مدیریت رسانه | B5: =COUNTIF('قابلیت‌ها'!$F$2:$F$368,A5) -> 28 | C5: =COUNTIFS('قابلیت‌ها'!$F$2:$F$368,A5,'قابلیت‌ها'!$I$2:$I$368,"✓") -> 0
A6: سکانس و تنظیمات پایه | B6: =COUNTIF('قابلیت‌ها'!$F$2:$F$368,A6) -> 10 | C6: =COUNTIFS('قابلیت‌ها'!$F$2:$F$368,A6,'قابلیت‌ها'!$I$2:$I$368,"✓") -> 0
A7: تدوین و تایم‌لاین | B7: =COUNTIF('قابلیت‌ها'!$F$2:$F$368,A7) -> 33 | C7: =COUNTIFS('قابلیت‌ها'!$F$2:$F$368,A7,'قابلیت‌ها'!$I$2:$I$368,"✓") -> 0
A8: سرعت و زمان | B8: =COUNTIF('قابلیت‌ها'!$F$2:$F$368,A8) -> 9 | C8: =COUNTIFS('قابلیت‌ها'!$F$2:$F$368,A8,'قابلیت‌ها'!$I$2:$I$368,"✓") -> 1
A9: حرکت، کی‌فریم و ماسک | B9: =COUNTIF('قابلیت‌ها'!$F$2:$F$368,A9) -> 16 | C9: =COUNTIFS('قابلیت‌ها'!$F$2:$F$368,A9,'قابلیت‌ها'!$I$2:$I$368,"✓") -> 0
A10: کلید و ترکیب | B10: =COUNTIF('قابلیت‌ها'!$F$2:$F$368,A10) -> 5 | C10: =COUNTIFS('قابلیت‌ها'!$F$2:$F$368,A10,'قابلیت‌ها'!$I$2:$I$368,"✓") -> 0
A11: تثبیت و ترمیم تصویر | B11: =COUNTIF('قابلیت‌ها'!$F$2:$F$368,A11) -> 5 | C11: =COUNTIFS('قابلیت‌ها'!$F$2:$F$368,A11,'قابلیت‌ها'!$I$2:$I$368,"✓") -> 5
A12: رنگ: لومتری (Lumetri) | B12: =COUNTIF('قابلیت‌ها'!$F$2:$F$368,A12) -> 20 | C12: =COUNTIFS('قابلیت‌ها'!$F$2:$F$368,A12,'قابلیت‌ها'!$I$2:$I$368,"✓") -> 7
A13: رنگ: مدیریت رنگ، HDR و حالت رنگ | B13: =COUNTIF('قابلیت‌ها'!$F$2:$F$368,A13) -> 7 | C13: =COUNTIFS('قابلیت‌ها'!$F$2:$F$368,A13,'قابلیت‌ها'!$I$2:$I$368,"✓") -> 1
A14: اسکوپ‌ها و اندازه‌گیری | B14: =COUNTIF('قابلیت‌ها'!$F$2:$F$368,A14) -> 4 | C14: =COUNTIFS('قابلیت‌ها'!$F$2:$F$368,A14,'قابلیت‌ها'!$I$2:$I$368,"✓") -> 0
A15: جلوه‌ی ویدیویی: تنظیم و رنگ | B15: =COUNTIF('قابلیت‌ها'!$F$2:$F$368,A15) -> 15 | C15: =COUNTIFS('قابلیت‌ها'!$F$2:$F$368,A15,'قابلیت‌ها'!$I$2:$I$368,"✓") -> 4
A16: جلوه‌ی ویدیویی: محو و شارپ | B16: =COUNTIF('قابلیت‌ها'!$F$2:$F$368,A16) -> 6 | C16: =COUNTIFS('قابلیت‌ها'!$F$2:$F$368,A16,'قابلیت‌ها'!$I$2:$I$368,"✓") -> 2
... A31: تکنیک‌های ترکیبی | B31: =COUNTIF('قابلیت‌ها'!$F$2:$F$368,A31) -> 8 | C31: =COUNTIFS('قابلیت‌ها'!$F$2:$F$368,A31,'قابلیت‌ها'!$I$2:$I$368,"✓") -> 1
A32: جمع | B32: =SUM(B5:B31) -> 367 | C32: =SUM(C5:C31) -> 47
A33: کنترل: تعداد کل ردیف‌های برگه‌ی قابلیت‌ها | B33: =COUNTA('قابلیت‌ها'!$B$2:$B$368) -> 367
A35: نوع پردازش | B35: تعداد قابلیت‌ها | C35: سهم از کل | D35: این نوع پردازش یعنی چه؟
A36: نقطه‌ای رنگ (هر پیکسل مستقل، LUT) | B36: =COUNTIF('قابلیت‌ها'!$H$2:$H$368,A36) -> 51 | C36: =IF($B$32=0,0,B36/$B$32) -> 0.13896458 | D36: رنگ جدید هر پیکسل فقط به رنگ قبلی همان پیکسل بستگی دارد؛ با جدول ازپیش‌حساب‌شده یا روی GPU برای همه‌ی پیکسل‌های هر فریم اجرا می‌شود.
A37: همسایگی مکانی (کانولوشن و فیلتر محلی) | B37: =COUNTIF('قابلیت‌ها'!$H$2:$H$368,A37) -> 28 | C37: =IF($B$32=0,0,B37/$B$32) -> 0.076294278 | D37: رنگ هر پیکسل از خودش و همسایه‌هایش در همان فریم حساب می‌شود: محو، شارپ، لبه‌یابی و سبک‌دهی.
A38: هندسی (نگاشت مختصات و درون‌یابی) | B38: =COUNTIF('قابلیت‌ها'!$H$2:$H$368,A38) -> 35 | C38: =IF($B$32=0,0,B38/$B$32) -> 0.095367847 | D38: پیکسل‌ها جابه‌جا می‌شوند؛ برای هر پیکسل خروجی مختصات مبدأ حساب و رنگش با درون‌یابی تخمین زده می‌شود.
A39: زمانی (بین فریم‌ها) | B39: =COUNTIF('قابلیت‌ها'!$H$2:$H$368,A39) -> 15 | C39: =IF($B$32=0,0,B39/$B$32) -> 0.040871935 | D39: خروجی هر فریم از فریم‌های دیگر ساخته می‌شود: تغییر سرعت، ترکیب فریم، تکرار یا حذف فریم.
A40: تخمین و ردیابی حرکت | B40: =COUNTIF('قابلیت‌ها'!$H$2:$H$368,A40) -> 6 | C40: =IF($B$32=0,0,B40/$B$32) -> 0.016348774 | D40: حرکت پیکسل‌ها یا نقاط ویژگی بین فریم‌ها تخمین زده می‌شود: جریان نوری، ردیابی ماسک و تثبیت تصویر.
A41: کلید و آلفا (ماتینگ) | B41: =COUNTIF('قابلیت‌ها'!$H$2:$H$368,A41) -> 6 | C41: =IF($B$32=0,0,B41/$B$32) -> 0.016348774 | D41: برای هر پیکسل میزان شفافیت (آلفا) از رنگ، روشنایی یا لایه‌ی دیگر محاسبه می‌شود.
A42: ترکیب لایه و شفافیت | B42: =COUNTIF('قابلیت‌ها'!$H$2:$H$368,A42) -> 22 | C42: =IF($B$32=0,0,B42/$B$32) -> 0.059945504 | D42: ترک‌ها و لایه‌ها با آلفا، ماسک و فرمول حالت ترکیب روی هم ترکیب می‌شوند؛ ترنزیشن‌های ماسکی هم در این گروه‌اند.
A43: تدوین غیرمخرب (ارجاع به رسانه) | B43: =COUNTIF('قابلیت‌ها'!$H$2:$H$368,A43) -> 20 | C43: =IF($B$32=0,0,B43/$B$32) -> 0.054495913 | D43: فقط ساختار داده‌ی تایم‌لاین (ارجاع به فایل، نقطه‌ی ورود و خروج، جایگاه) تغییر می‌کند و فایل اصلی دست نمی‌خورد.
A44: پردازش سیگنال صوتی (DSP) | B44: =COUNTIF('قابلیت‌ها'!$H$2:$H$368,A44) -> 53 | C44: =IF($B$32=0,0,B44/$B$32) -> 0.14441417 | D44: عملیات روی نمونه‌های صدا در حوزه‌ی زمان (بهره، تأخیر، فشرده‌سازی) یا حوزه‌ی فرکانس (FFT و فیلترها).
A45: برداری و گرافیک | B45: =COUNTIF('قابلیت‌ها'!$H$2:$H$368,A45) -> 8 | C45: =IF($B$32=0,0,B45/$B$32) -> 0.021798365 | D45: شکل و متن با معادله‌ی منحنی‌ها ذخیره و در هر اندازه بدون افت کیفیت پیکسلی می‌شوند.
A46: هوش مصنوعی روی دستگاه | B46: =COUNTIF('قابلیت‌ها'!$H$2:$H$368,A46) -> 17 | C46: =IF($B$32=0,0,B46/$B$32) -> 0.046321526 | D46: شبکه‌ی عصبی آموزش‌دیده که روی کارت گرافیک یا پردازنده‌ی خود سیستم اجرا می‌شود.
A47: هوش مصنوعی (دستگاه یا ابر) | B47: =COUNTIF('قابلیت‌ها'!$H$2:$H$368,A47) -> 3 | C47: =IF($B$32=0,0,B47/$B$32) -> 0.0081743869 | D47: شبکه‌ی عصبی که بسته به قابلیت و تنظیمات، روی سیستم یا روی سرورهای ادوبی اجرا می‌شود.
... A53: مدیریتی، رابط و جریان کار | B53: =COUNTIF('قابلیت‌ها'!$H$2:$H$368,A53) -> 61 | C53: =IF($B$32=0,0,B53/$B$32) -> 0.16621253 | D53: مدیریت پروژه، پنل‌ها، نمایش، اندازه‌گیری، تنظیمات و ابزارهای کمکی.
A54: جمع | B54: =SUM(B36:B53) -> 367 | C54: =SUM(C36:C53) -> 1

Sheet راهنما
A1: پایگاه داده‌ی قابلیت‌های پریمیر ‪(Adobe Premiere / Premiere Pro)‬: کاربرد و پشت صحنه
A2: این فایل قابلیت‌های پریمیر را دسته‌بندی کرده و برای هرکدام می‌گوید چه کار می‌کند، هدفش چیست و پریمیر پشت صحنه چطور آن را انجام می‌دهد. تعداد قابلیت‌های هر دسته در برگه‌ی «خلاصه» آمده است.
A3: مبنا: نسخه‌ی ۲۶.۵ (سپتامبر ۲۰۲۶). ادوبی در صفحه‌های جدید راهنما نام برنامه را Adobe Premiere می‌نویسد. قابلیت‌های بتا با کلمه‌ی Beta مشخص شده‌اند و ممکن است تغییر کنند یا روی همه‌ی حساب‌ها فعال نباشند.
A4: میان‌برها برای ویندوز و چیدمان پیش‌فرض صفحه‌کلید نوشته شده‌اند؛ در مک به‌جای Ctrl از Cmd و به‌جای Alt از Option استفاده کنید.
A5: ستون‌های برگه‌ی «قابلیت‌ها»
A6: ردیف: شماره‌ی ثابت هر قابلیت؛ با مرتب‌سازی و فیلتر عوض نمی‌شود.
A7: قابلیت (نام در پریمیر): نام انگلیسی همان‌طور که در منوها، پنل‌ها و فهرست جلوه‌ها دیده می‌شود.
A8: نام فارسی: معادل فارسی برای جست‌وجو و فهم راحت‌تر.
A9: چه کار می‌کند و هدفش چیست: کاربرد عملی قابلیت و اینکه به چه دردی می‌خورد.
A10: پشت صحنه: الگوریتم، مدل ریاضی یا ساختار داده‌ای که پریمیر برای انجام این کار به کار می‌برد.
A11: دسته: گروه موضوعی قابلیت.
A12: کجا / میان‌بر: مسیر منو، پنل یا کلید میان‌بر. جلوه‌ها را می‌توانید با تایپ نامشان در کادر جست‌وجوی پنل Effects پیدا کنید.
... A48: برای دیدن فقط یک دسته، یک نوع پردازش یا فقط قابلیت‌های ارتقای کیفیت، روی فلش فیلتر در سرستون برگه‌ی «قابلیت‌ها» کلیک کنید. ستون‌های «ردیف»، «قابلیت» و «نام فارسی» هنگام اسکرول افقی ثابت می‌مانند.
